<?xml version="1.0" ?>

<robot name="snake">

    <link name="ball_0" >
      <inertial>
              <origin rpy = "0 0 0" xyz = "0.000000 0.000000 0.000000" />
           <mass value = "0.500000" />
          <inertia ixx = "0.1" ixy = "0" ixz = "0" iyy = "0.1" iyz = "0" izz = "0.1" />
      </inertial>
      <collision>
              <origin rpy = "0 0 0" xyz = "0.000000 0.000000 0.000000" />
          <geometry>
              <sphere radius = "0.080000" />
          </geometry>
      </collision>
  </link>

  <joint name="ball_joint_0" type="fixed" >
      <parent link="ball_0" />
      <child link="right_shoulder" />
      <limit effort="1000.0" lower="0" upper="3.14" velocity="0.5"/>
              <origin rpy = "0 0 0" xyz = "0.000000 -0.40000 0.000000" />
      <axis xyz = "0.000000 0.000000 1.000000" />
  </joint>

  <link name="right_shoulder" >
      <inertial>
              <origin rpy = "0 0 0" xyz = "0.000000 -0.000000 0.000000" />
           <mass value = "1.00000" />
          <inertia ixx = "0.1" ixy = "0" ixz = "0" iyy = "0.1" iyz = "0" izz = "0.1" />
      </inertial>
      <collision>
              <origin rpy = "-1.570796 0 0" xyz = "0.000000 -0.000000 0.000000" />
          <geometry>
              <capsule length="0.440000" radius="0.050000"/>
          </geometry>
      </collision>
  </link>

  <joint name="right_elbow" type="revolute" >
      <parent link="right_shoulder" />
      <child link="ball_1" />
      <limit effort="1000.0" lower="0" upper="3.14" velocity="0.5"/>
              <origin rpy = "0 0 0" xyz = "0.000000 -0.40000 0.000000" />
      <axis xyz = "0.000000 0.000000 1.000000" />
  </joint>

  <link name="ball_1" >
      <inertial>
              <origin rpy = "0 0 0" xyz = "0.000000 0.000000 0.000000" />
           <mass value = "0.500000" />
          <inertia ixx = "0.1" ixy = "0" ixz = "0" iyy = "0.1" iyz = "0" izz = "0.1" />
      </inertial>
      <collision>
              <origin rpy = "0 0 0" xyz = "0.000000 0.000000 0.000000" />
          <geometry>
              <sphere radius = "0.080000" />
          </geometry>
      </collision>
  </link>

  <joint name="ball_joint_1" type="fixed" >
      <parent link="ball_1" />
      <child link="link_1" />
        <origin rpy = "0 0 0" xyz = "0.000000 -0.4000 0.000000" />
  </joint>

  <link name="link_1" >
      <inertial>
              <origin rpy = "0 0 0" xyz = "0.000000 -0.000000 0.000000" />
           <mass value = "1.000000" />
          <inertia ixx = "0.1" ixy = "0" ixz = "0" iyy = "0.1" iyz = "0" izz = "0.1" />
      </inertial>
      <collision>
              <origin rpy = "-1.570796 0 0" xyz = "0.000000 -0.000000 0.000000" />
          <geometry>
              <capsule length="0.440000" radius="0.050000"/>
          </geometry>
      </collision>
  </link>


  <!-- BLOCK 2 -->

  <joint name="joint_1" type="revolute" >
      <parent link="link_1" />
      <child link="ball_2" />
      <limit effort="1000.0" lower="0" upper="3.14" velocity="0.5"/>
              <origin rpy = "0 0 0" xyz = "0.000000 -0.40000 0.000000" />
      <axis xyz = "0.000000 0.000000 1.000000" />
  </joint>

  <link name="ball_2" >
      <inertial>
              <origin rpy = "0 0 0" xyz = "0.000000 0.000000 0.000000" />
           <mass value = "0.500000" />
          <inertia ixx = "0.1" ixy = "0" ixz = "0" iyy = "0.1" iyz = "0" izz = "0.1" />
      </inertial>
      <collision>
              <origin rpy = "0 0 0" xyz = "0.000000 0.000000 0.000000" />
          <geometry>
              <sphere radius = "0.080000" />
          </geometry>
      </collision>
  </link>

  <joint name="ball_joint_2" type="fixed" >
      <parent link="ball_2" />
      <child link="link_2" />
        <origin rpy = "0 0 0" xyz = "0.000000 -0.4000 0.000000" />
  </joint>

  <link name="link_2" >
      <inertial>
              <origin rpy = "0 0 0" xyz = "0.000000 -0.000000 0.000000" />
           <mass value = "1.000000" />
          <inertia ixx = "0.1" ixy = "0" ixz = "0" iyy = "0.1" iyz = "0" izz = "0.1" />
      </inertial>
      <collision>
              <origin rpy = "-1.570796 0 0" xyz = "0.000000 -0.000000 0.000000" />
          <geometry>
              <capsule length="0.440000" radius="0.050000"/>
          </geometry>
      </collision>
  </link>

  <!-- BLOCK 3 -->

  <joint name="joint_2" type="revolute" >
      <parent link="link_2" />
      <child link="ball_3" />
      <limit effort="1000.0" lower="0" upper="3.14" velocity="0.5"/>
              <origin rpy = "0 0 0" xyz = "0.000000 -0.40000 0.000000" />
      <axis xyz = "0.000000 0.000000 1.000000" />
  </joint>

  <link name="ball_3" >
      <inertial>
              <origin rpy = "0 0 0" xyz = "0.000000 0.000000 0.000000" />
           <mass value = "0.500000" />
          <inertia ixx = "0.1" ixy = "0" ixz = "0" iyy = "0.1" iyz = "0" izz = "0.1" />
      </inertial>
      <collision>
              <origin rpy = "0 0 0" xyz = "0.000000 0.000000 0.000000" />
          <geometry>
              <sphere radius = "0.080000" />
          </geometry>
      </collision>
  </link>

  <joint name="ball_joint_3" type="fixed" >
      <parent link="ball_3" />
      <child link="link_3" />
        <origin rpy = "0 0 0" xyz = "0.000000 -0.4000 0.000000" />
  </joint>

  <link name="link_3" >
      <inertial>
              <origin rpy = "0 0 0" xyz = "0.000000 -0.000000 0.000000" />
           <mass value = "1.000000" />
          <inertia ixx = "0.1" ixy = "0" ixz = "0" iyy = "0.1" iyz = "0" izz = "0.1" />
      </inertial>
      <collision>
              <origin rpy = "-1.570796 0 0" xyz = "0.000000 -0.000000 0.000000" />
          <geometry>
              <capsule length="0.440000" radius="0.050000"/>
          </geometry>
      </collision>
  </link>


  <!-- BLOCK 4 -->

  <joint name="joint_3" type="revolute" >
      <parent link="link_3" />
      <child link="ball_4" />
      <limit effort="1000.0" lower="0" upper="3.14" velocity="0.5"/>
              <origin rpy = "0 0 0" xyz = "0.000000 -0.40000 0.000000" />
      <axis xyz = "0.000000 0.000000 1.000000" />
  </joint>

  <link name="ball_4" >
      <inertial>
              <origin rpy = "0 0 0" xyz = "0.000000 0.000000 0.000000" />
           <mass value = "0.500000" />
          <inertia ixx = "0.1" ixy = "0" ixz = "0" iyy = "0.1" iyz = "0" izz = "0.1" />
      </inertial>
      <collision>
              <origin rpy = "0 0 0" xyz = "0.000000 0.000000 0.000000" />
          <geometry>
              <sphere radius = "0.080000" />
          </geometry>
      </collision>
  </link>

  <joint name="ball_joint_4" type="fixed" >
      <parent link="ball_4" />
      <child link="link_4" />
        <origin rpy = "0 0 0" xyz = "0.000000 -0.4000 0.000000" />
  </joint>

  <link name="link_4" >
      <inertial>
              <origin rpy = "0 0 0" xyz = "0.000000 -0.000000 0.000000" />
           <mass value = "1.000000" />
          <inertia ixx = "0.1" ixy = "0" ixz = "0" iyy = "0.1" iyz = "0" izz = "0.1" />
      </inertial>
      <collision>
              <origin rpy = "-1.570796 0 0" xyz = "0.000000 -0.000000 0.000000" />
          <geometry>
              <capsule length="0.440000" radius="0.050000"/>
          </geometry>
      </collision>
  </link>

</robot>

